<?xml version='1.0'?>
<sdf version='1.11'>
  <model name='dof_URDF_5'>
    <ros2_control name="GazeboSimSystem" type="system">
      <hardware>
        <plugin>gz_ros2_control/GazeboSimSystem</plugin>
      </hardware>
      <joint name="joint_0">
        <command_interface name="position">
          <param name="min">0.0</param>
          <param name="max">1.0</param>
        </command_interface>
        <state_interface name="position">
          <param name="initial_value">1.0</param>
        </state_interface>
        <state_interface name="position"/>
        <state_interface name="velocity"/>
      </joint>
      <joint name="joint_1">
        <command_interface name="position">
          <param name="min">0.0</param>
          <param name="max">1.0</param>
        </command_interface>
        <state_interface name="position">
          <param name="initial_value">1.0</param>
        </state_interface>
        <state_interface name="position"/>
        <state_interface name="velocity"/>
      </joint>
      <joint name="joint_2">
        <command_interface name="position">
          <param name="min">0.0</param>
          <param name="max">1.0</param>
        </command_interface>
        <state_interface name="position">
          <param name="initial_value">1.0</param>
        </state_interface>
        <state_interface name="position"/>
        <state_interface name="velocity"/>
      </joint>
      <joint name="joint_3">
        <command_interface name="position">
          <param name="min">0.0</param>
          <param name="max">1.0</param>
        </command_interface>
        <state_interface name="position"/>
        <state_interface name="velocity"/>
      </joint>
    </ros2_control>


    <!-- plugin -->
    <plugin filename="libgz_ros2_control-system.so" name="gz_ros2_control::GazeboSimROS2ControlPlugin">
      <parameters>/home/venus/ros2_ws/src/cli_spawn/connfig/myrobot_control.yaml</parameters>
    </plugin>
    <!-- joint & link -->
    <joint name="world_fixed_joint" type="fixed">
      <parent>world</parent>
      <child>base_link</child>
    </joint>
    <link name='base_link'>
      <inertial>
        <pose>2.5050248345575099 -0.69797390422029904 -0.14193534101223601 0 0 0</pose>
        <mass>23.8354068968255</mass>
        <inertia>
          <ixx>0.48183039956020002</ixx>
          <ixy>-2.3528304727728401e-05</ixy>
          <ixz>4.7680915528978703e-05</ixz>
          <iyy>0.50048709423294002</iyy>
          <iyz>-0.0195171079206608</iyz>
          <izz>0.36928587455240502</izz>
        </inertia>
      </inertial>
      <collision name='base_link_collision'>
        <pose>0 0 0 0 0 0</pose>
        <geometry>
          <mesh>
            <scale>1 1 1</scale>
            <uri>file:///home/venus/ros2_ws/src/cli_spawn/meshes/base_link.STL</uri>
          </mesh>
        </geometry>
      </collision>
      <visual name='base_link_visual'>
        <pose>0 0 0 0 0 0</pose>
        <geometry>
          <mesh>
            <scale>1 1 1</scale>
            <uri>file:///home/venus/ros2_ws/src/cli_spawn/meshes/base_link.STL</uri>
          </mesh>
        </geometry>
        <material>
          <diffuse>0.25 0.25 0.25 1</diffuse>
          <ambient>0.25 0.25 0.25 1</ambient>
        </material>
      </visual>
    </link>
    
    <joint name='joint_0' type='revolute'>
      <pose relative_to='base_link'>2.5049999999999999 0.16780999999999999 -0.32162000000000002 1.5708 -1.3877787807814457e-17 2.9232</pose>
      <parent>base_link</parent>
      <child>link_1</child>
      <axis>
        <xyz>0 1 0</xyz>
        <limit>
          <lower>-1.57</lower>
          <upper>1.57</upper>
          <effort>5.0</effort>
          <velocity>10.0</velocity>
        </limit>
        <dynamics>
          <spring_reference>0</spring_reference>
          <spring_stiffness>0</spring_stiffness>
        </dynamics>
      </axis>
    </joint>
    
    <link name='link_1'>
      <pose relative_to='joint_0'>0 0 0 0 0 0</pose>
      <inertial>
        <pose>4.4408920985006301e-16 -0.130581484630826 -7.4384942649885504e-15 0 0 0</pose>
        <mass>2.98648132353624</mass>
        <inertia>
          <ixx>0.024095478278114899</ixx>
          <ixy>1.6466089522496199e-17</ixy>
          <ixz>4.7704895589362203e-18</ixz>
          <iyy>0.0105603189198943</iyy>
          <iyz>6.6602720654976e-18</iyz>
          <izz>0.023097390040476801</izz>
        </inertia>
      </inertial>
      <collision name='link_1_collision'>
        <pose>0 0 0 0 0 0</pose>
        <geometry>
          <mesh>
            <scale>1 1 1</scale>
            <uri>file:///home/venus/ros2_ws/src/cli_spawn/meshes/link_1.STL</uri>
          </mesh>
        </geometry>
      </collision>
      <visual name='link_1_visual'>
        <pose>0 0 0 0 0 0</pose>
        <geometry>
          <mesh>
            <scale>1 1 1</scale>
            <uri>file:///home/venus/ros2_ws/src/cli_spawn/meshes/link_1.STL</uri>
          </mesh>
        </geometry>
        <material>
          <diffuse>0.990196109 1 1 1</diffuse>
          <ambient>0.990196109 1 1 1</ambient>
        </material>
      </visual>
    </link>
    
    <joint name='joint_1' type='revolute'>
      <pose relative_to='link_1'>0 -0.074999999999999997 0 -3.1415853071795872 0 -2.9590999999999998</pose>
      <parent>link_1</parent>
      <child>link_2</child>
      <axis>
        <xyz>0 0 1</xyz>
        <limit>
          <lower>-1.57</lower>
          <upper>1.57</upper>
          <effort>5.0</effort>
          <velocity>10.0</velocity>
        </limit>
        <dynamics>
          <spring_reference>0</spring_reference>
          <spring_stiffness>0</spring_stiffness>
        </dynamics>
      </axis>
    </joint>
    
    <link name='link_2'>
      <pose relative_to='joint_1'>0 0 0 0 0 0</pose>
      <inertial>
        <pose>-1.33226762955019e-15 0.098401308785062397 -2.40747497159965e-06 0 0 0</pose>
        <mass>3.1988210103973702</mass>
        <inertia>
          <ixx>0.0587854336457432</ixx>
          <ixy>7.9423230145425598e-16</ixy>
          <ixz>2.6888213877640501e-17</ixz>
          <iyy>0.016602340998814101</iyy>
          <iyz>1.3314359121166601e-06</iyz>
          <izz>0.046963499504171398</izz>
        </inertia>
      </inertial>
      <collision name='link_2_collision'>
        <pose>0 0 0 0 0 0</pose>
        <geometry>
          <mesh>
            <scale>1 1 1</scale>
            <uri>file:///home/venus/ros2_ws/src/cli_spawn/meshes/link_2.STL</uri>
          </mesh>
        </geometry>
      </collision>
      <visual name='link_2_visual'>
        <pose>0 0 0 0 0 0</pose>
        <geometry>
          <mesh>
            <scale>1 1 1</scale>
            <uri>file:///home/venus/ros2_ws/src/cli_spawn/meshes/link_2.STL</uri>
          </mesh>
        </geometry>
        <material>
          <diffuse>0.990196109 1 1 1</diffuse>
          <ambient>0.990196109 1 1 1</ambient>
        </material>
      </visual>
    </link>
    
    <joint name='joint_2' type='revolute'>
      <pose relative_to='link_2'>0 0.25 0 3.1415853071795872 0 -0.16373999999999997</pose>
      <parent>link_2</parent>
      <child>link_3</child>
      <axis>
        <xyz>0 0 1</xyz>
        <limit>
          <lower>-1.57</lower>
          <upper>1.57</upper>
          <effort>5.0</effort>
          <velocity>10.0</velocity>
        </limit>
        <dynamics>
          <spring_reference>0</spring_reference>
          <spring_stiffness>0</spring_stiffness>
        </dynamics>
      </axis>
    </joint>
    
    <link name='link_3'>
      <pose relative_to='joint_2'>0 0 0 0 0 0</pose>
      <inertial>
        <pose>-0.132034284435224 5.1070259132757201e-15 1.0000000094656501e-07 0 0 0</pose>
        <mass>4.95602940256141</mass>
        <inertia>
          <ixx>0.021205123886585599</ixx>
          <ixy>-4.6623403922307904e-16</ixy>
          <ixz>2.1684043449710101e-17</ixz>
          <iyy>0.044102174926398799</iyy>
          <iyz>-1.47451495458029e-17</iyz>
          <izz>0.038354520018927397</izz>
        </inertia>
      </inertial>
      <collision name='link_3_collision'>
        <pose>0 0 0 0 0 0</pose>
        <geometry>
          <mesh>
            <scale>1 1 1</scale>
            <uri>file:///home/venus/ros2_ws/src/cli_spawn/meshes/link_3.STL</uri>
          </mesh>
        </geometry>
      </collision>
      <visual name='link_3_visual'>
        <pose>0 0 0 0 0 0</pose>
        <geometry>
          <mesh>
            <scale>1 1 1</scale>
            <uri>file:///home/venus/ros2_ws/src/cli_spawn/meshes/link_3.STL</uri>
          </mesh>
        </geometry>
        <material>
          <diffuse>0.990196109 1 1 1</diffuse>
          <ambient>0.990196109 1 1 1</ambient>
        </material>
      </visual>
    </link>
    
    <joint name='joint_3' type='revolute'>
      <pose relative_to='link_3'>-0.20116000000000001 0 0 1.5707999999999935 -1.5365999999999975 -1.5707999999999922</pose>
      <parent>link_3</parent>
      <child>link_4</child>
      <axis>
        <xyz>0 0 1</xyz>
        <limit>
          <lower>-1.57</lower>
          <upper>1.57</upper>
          <effort>5.0</effort>
          <velocity>10.0</velocity>
        </limit>
        <dynamics>
          <spring_reference>0</spring_reference>
          <spring_stiffness>0</spring_stiffness>
        </dynamics>
      </axis>
    </joint>
    
    <link name='link_4'>
      <pose relative_to='joint_3'>0 0 0 0 0 0</pose>
      <inertial>
        <pose>2.9976021664879199e-15 -6.2172489379008798e-15 0.091396265787680004 0 0 0</pose>
        <mass>0.63942080340798</mass>
        <inertia>
          <ixx>0.0028704207901047602</ixx>
          <ixy>8.5866164478832595e-18</ixy>
          <ixz>-6.6669922241695497e-18</ixz>
          <iyy>0.00287041793755319</iyy>
          <iyz>-4.94589255675409e-17</iyz>
          <izz>0.0019234857448842601</izz>
        </inertia>
      </inertial>
      <collision name='link_4_collision'>
        <pose>0 0 0 0 0 0</pose>
        <geometry>
          <mesh>
            <scale>1 1 1</scale>
            <uri>file:///home/venus/ros2_ws/src/cli_spawn/meshes/link_4.STL</uri>
          </mesh>
        </geometry>
      </collision>
      <visual name='link_4_visual'>
        <pose>0 0 0 0 0 0</pose>
        <geometry>
          <mesh>
            <scale>1 1 1</scale>
            <uri>file:///home/venus/ros2_ws/src/cli_spawn/meshes/link_4.STL</uri>
          </mesh>
        </geometry>
        <material>
          <diffuse>0.990196109 1 1 1</diffuse>
          <ambient>0.990196109 1 1 1</ambient>
        </material>
      </visual>
    </link>
    
    <joint name='joint_4' type='revolute'>
      <pose relative_to='link_4'>0 0.18000000000000002 0 1.5707963267948968 1.5707963267948968 1.5707963267948968</pose>
      <parent>link_4</parent>
      <child>link_5</child>
      <axis>
        <xyz>0 0 1</xyz>
        <limit>
          <lower>-1.57</lower>
          <upper>1.57</upper>
          <effort>5.0</effort>
          <velocity>10.0</velocity>
        </limit>
        <dynamics>
          <spring_reference>0</spring_reference>
          <spring_stiffness>0</spring_stiffness>
        </dynamics>
      </axis>
    </joint>
    
    <link name='link_5'>
      <pose relative_to='joint_4'>0 0 0 0 0 0</pose>
      <inertial>
        <pose>-0.016335198086036101 0.0538053670987309 -0.00767557342621936 0 0 0</pose>
        <mass>0.106518175402096</mass>
        <inertia>
          <ixx>4.2691517454944903e-05</ixx>
          <ixy>8.1634789508544903e-06</ixy>
          <ixz>-6.9922097062145596e-06</ixz>
          <iyy>3.2104193584852099e-05</iyy>
          <iyz>-4.4447432652230598e-07</iyz>
          <izz>2.7483661132644298e-05</izz>
        </inertia>
      </inertial>
      <visual name='link_5_visual'>
        <pose>0 0 0 0 0 0</pose>
        <geometry>
          <mesh>
            <scale>1 1 1</scale>
            <uri>file:///home/venus/ros2_ws/src/cli_spawn/meshes/link_5.STL</uri>
          </mesh>
        </geometry>
        <material>
          <diffuse>0.990196109 1 1 1</diffuse>
          <ambient>0.990196109 1 1 1</ambient>
        </material>
      </visual>
      <collision name='link_5_collision'>
        <pose>0 0 0 0 0 0</pose>
        <geometry>
          <mesh>
            <scale>1 1 1</scale>
            <uri>file:///home/venus/ros2_ws/src/cli_spawn/meshes/link_5.STL</uri>
          </mesh>
        </geometry>
      </collision>
    </link>
    
  </model>
</sdf>

